2020:04:01 13:02:44:144873 ~ Traceback (most recent call last):
  File "C:\SDK\Anaconda3\lib\site-packages\pydebugger\debug.py", line 222, in read_config
    data = self.cfg.get(section, option)
  File "C:\SDK\Anaconda3\lib\configparser.py", line 780, in get
    d = self._unify_values(section, vars)
  File "C:\SDK\Anaconda3\lib\configparser.py", line 1146, in _unify_values
    raise NoSectionError(section) from None
configparser.NoSectionError: No section: 'DEBUG'

2020:04:01 13:02:45:234010 ~ Traceback (most recent call last):
  File "D:\TOOLS\pyx\gitdate.py", line 218, in notify
    import PySnarl
ModuleNotFoundError: No module named 'PySnarl'

2020:04:01 13:02:46:367343 ~ Traceback (most recent call last):
  File "D:\TOOLS\pyx\gitdate.py", line 218, in notify
    import PySnarl
ModuleNotFoundError: No module named 'PySnarl'

2020:04:01 13:02:47:659350 ~ Traceback (most recent call last):
  File "D:\TOOLS\pyx\gitdate.py", line 218, in notify
    import PySnarl
ModuleNotFoundError: No module named 'PySnarl'

2020:04:01 13:02:48:685246 ~ Traceback (most recent call last):
  File "D:\TOOLS\pyx\gitdate.py", line 218, in notify
    import PySnarl
ModuleNotFoundError: No module named 'PySnarl'

2020:04:01 13:02:49:515794 ~ Traceback (most recent call last):
  File "D:\TOOLS\pyx\gitdate.py", line 732, in commit
    if 'https:' in host or 'http:' in host or 'ssh:' in host or 'git:' in host:
TypeError: argument of type 'bool' is not iterable

2020:05:25 21:28:13:166000 ~ Traceback (most recent call last):
  File "D:\TOOLS\pyx\gitdate.py", line 757, in commit
    host = format_git_remote(i.get('url'))
  File "D:\TOOLS\pyx\gitdate.py", line 434, in format_git_remote
    username = input('[%s] USERNAME: ' % (flag))
  File "<string>", line 1
    cumulus13@gmail.com
             ^
SyntaxError: invalid syntax

2020:06:08 08:47:56:485000 ~ Traceback (most recent call last):
  File "c:\SDK\Anaconda2\lib\site-packages\notify\notify.py", line 158, in nmd
    a = requests.post(url, data = data, timeout = timeout)
  File "c:\SDK\Anaconda2\lib\site-packages\requests\api.py", line 119, in post
    return request('post', url, data=data, json=json, **kwargs)
  File "c:\SDK\Anaconda2\lib\site-packages\requests\api.py", line 61, in request
    return session.request(method=method, url=url, **kwargs)
  File "c:\SDK\Anaconda2\lib\site-packages\requests\sessions.py", line 530, in request
    resp = self.send(prep, **send_kwargs)
  File "c:\SDK\Anaconda2\lib\site-packages\requests\sessions.py", line 643, in send
    r = adapter.send(request, **kwargs)
  File "c:\SDK\Anaconda2\lib\site-packages\requests\adapters.py", line 516, in send
    raise ConnectionError(e, request=request)
ConnectionError: HTTPSConnectionPool(host='www.notifymydevice.com', port=443): Max retries exceeded with url: /push (Caused by NewConnectionError('<urllib3.connection.VerifiedHTTPSConnection object at 0x0000000004567278>: Failed to establish a new connection: [Errno 11001] getaddrinfo failed',))

2020:06:08 08:48:02:003000 ~ Traceback (most recent call last):
  File "c:\SDK\Anaconda2\lib\site-packages\notify\notify.py", line 158, in nmd
    a = requests.post(url, data = data, timeout = timeout)
  File "c:\SDK\Anaconda2\lib\site-packages\requests\api.py", line 119, in post
    return request('post', url, data=data, json=json, **kwargs)
  File "c:\SDK\Anaconda2\lib\site-packages\requests\api.py", line 61, in request
    return session.request(method=method, url=url, **kwargs)
  File "c:\SDK\Anaconda2\lib\site-packages\requests\sessions.py", line 530, in request
    resp = self.send(prep, **send_kwargs)
  File "c:\SDK\Anaconda2\lib\site-packages\requests\sessions.py", line 643, in send
    r = adapter.send(request, **kwargs)
  File "c:\SDK\Anaconda2\lib\site-packages\requests\adapters.py", line 516, in send
    raise ConnectionError(e, request=request)
ConnectionError: HTTPSConnectionPool(host='www.notifymydevice.com', port=443): Max retries exceeded with url: /push (Caused by NewConnectionError('<urllib3.connection.VerifiedHTTPSConnection object at 0x00000000046D3908>: Failed to establish a new connection: [Errno 11001] getaddrinfo failed',))

2020:06:08 09:48:06:949000 ~ Traceback (most recent call last):
  File "c:\SDK\Anaconda2\lib\site-packages\notify\notify.py", line 158, in nmd
    a = requests.post(url, data = data, timeout = timeout)
  File "c:\SDK\Anaconda2\lib\site-packages\requests\api.py", line 119, in post
    return request('post', url, data=data, json=json, **kwargs)
  File "c:\SDK\Anaconda2\lib\site-packages\requests\api.py", line 61, in request
    return session.request(method=method, url=url, **kwargs)
  File "c:\SDK\Anaconda2\lib\site-packages\requests\sessions.py", line 530, in request
    resp = self.send(prep, **send_kwargs)
  File "c:\SDK\Anaconda2\lib\site-packages\requests\sessions.py", line 643, in send
    r = adapter.send(request, **kwargs)
  File "c:\SDK\Anaconda2\lib\site-packages\requests\adapters.py", line 514, in send
    raise SSLError(e, request=request)
SSLError: HTTPSConnectionPool(host='www.notifymydevice.com', port=443): Max retries exceeded with url: /push (Caused by SSLError(SSLError("bad handshake: Error([('SSL routines', 'ssl3_get_server_certificate', 'certificate verify failed')],)",),))

2020:06:09 05:48:30:970000 ~ Traceback (most recent call last):
  File "c:\SDK\Anaconda2\lib\site-packages\notify\notify.py", line 158, in nmd
    a = requests.post(url, data = data, timeout = timeout)
  File "c:\SDK\Anaconda2\lib\site-packages\requests\api.py", line 119, in post
    return request('post', url, data=data, json=json, **kwargs)
  File "c:\SDK\Anaconda2\lib\site-packages\requests\api.py", line 61, in request
    return session.request(method=method, url=url, **kwargs)
  File "c:\SDK\Anaconda2\lib\site-packages\requests\sessions.py", line 530, in request
    resp = self.send(prep, **send_kwargs)
  File "c:\SDK\Anaconda2\lib\site-packages\requests\sessions.py", line 643, in send
    r = adapter.send(request, **kwargs)
  File "c:\SDK\Anaconda2\lib\site-packages\requests\adapters.py", line 514, in send
    raise SSLError(e, request=request)
SSLError: HTTPSConnectionPool(host='www.notifymydevice.com', port=443): Max retries exceeded with url: /push (Caused by SSLError(SSLError("bad handshake: Error([('SSL routines', 'ssl3_get_server_certificate', 'certificate verify failed')],)",),))

2020:06:10 07:49:20:673000 ~ Traceback (most recent call last):
  File "c:\SDK\Anaconda2\lib\site-packages\notify\notify.py", line 158, in nmd
    a = requests.post(url, data = data, timeout = timeout)
  File "c:\SDK\Anaconda2\lib\site-packages\requests\api.py", line 119, in post
    return request('post', url, data=data, json=json, **kwargs)
  File "c:\SDK\Anaconda2\lib\site-packages\requests\api.py", line 61, in request
    return session.request(method=method, url=url, **kwargs)
  File "c:\SDK\Anaconda2\lib\site-packages\requests\sessions.py", line 530, in request
    resp = self.send(prep, **send_kwargs)
  File "c:\SDK\Anaconda2\lib\site-packages\requests\sessions.py", line 643, in send
    r = adapter.send(request, **kwargs)
  File "c:\SDK\Anaconda2\lib\site-packages\requests\adapters.py", line 514, in send
    raise SSLError(e, request=request)
SSLError: HTTPSConnectionPool(host='www.notifymydevice.com', port=443): Max retries exceeded with url: /push (Caused by SSLError(SSLError("bad handshake: Error([('SSL routines', 'ssl3_get_server_certificate', 'certificate verify failed')],)",),))

2020:06:11 04:48:04:526000 ~ Traceback (most recent call last):
  File "c:\SDK\Anaconda2\lib\site-packages\notify\notify.py", line 158, in nmd
    a = requests.post(url, data = data, timeout = timeout)
  File "c:\SDK\Anaconda2\lib\site-packages\requests\api.py", line 119, in post
    return request('post', url, data=data, json=json, **kwargs)
  File "c:\SDK\Anaconda2\lib\site-packages\requests\api.py", line 61, in request
    return session.request(method=method, url=url, **kwargs)
  File "c:\SDK\Anaconda2\lib\site-packages\requests\sessions.py", line 530, in request
    resp = self.send(prep, **send_kwargs)
  File "c:\SDK\Anaconda2\lib\site-packages\requests\sessions.py", line 643, in send
    r = adapter.send(request, **kwargs)
  File "c:\SDK\Anaconda2\lib\site-packages\requests\adapters.py", line 514, in send
    raise SSLError(e, request=request)
SSLError: HTTPSConnectionPool(host='www.notifymydevice.com', port=443): Max retries exceeded with url: /push (Caused by SSLError(SSLError("bad handshake: Error([('SSL routines', 'ssl3_get_server_certificate', 'certificate verify failed')],)",),))

2020:06:12 05:19:04:117000 ~ Traceback (most recent call last):
  File "c:\SDK\Anaconda2\lib\site-packages\notify\notify.py", line 158, in nmd
    a = requests.post(url, data = data, timeout = timeout)
  File "c:\SDK\Anaconda2\lib\site-packages\requests\api.py", line 119, in post
    return request('post', url, data=data, json=json, **kwargs)
  File "c:\SDK\Anaconda2\lib\site-packages\requests\api.py", line 61, in request
    return session.request(method=method, url=url, **kwargs)
  File "c:\SDK\Anaconda2\lib\site-packages\requests\sessions.py", line 530, in request
    resp = self.send(prep, **send_kwargs)
  File "c:\SDK\Anaconda2\lib\site-packages\requests\sessions.py", line 643, in send
    r = adapter.send(request, **kwargs)
  File "c:\SDK\Anaconda2\lib\site-packages\requests\adapters.py", line 514, in send
    raise SSLError(e, request=request)
SSLError: HTTPSConnectionPool(host='www.notifymydevice.com', port=443): Max retries exceeded with url: /push (Caused by SSLError(SSLError("bad handshake: Error([('SSL routines', 'ssl3_get_server_certificate', 'certificate verify failed')],)",),))

2020:06:12 23:49:47:758000 ~ Traceback (most recent call last):
  File "c:\SDK\Anaconda2\lib\site-packages\notify\notify.py", line 158, in nmd
    a = requests.post(url, data = data, timeout = timeout)
  File "c:\SDK\Anaconda2\lib\site-packages\requests\api.py", line 119, in post
    return request('post', url, data=data, json=json, **kwargs)
  File "c:\SDK\Anaconda2\lib\site-packages\requests\api.py", line 61, in request
    return session.request(method=method, url=url, **kwargs)
  File "c:\SDK\Anaconda2\lib\site-packages\requests\sessions.py", line 530, in request
    resp = self.send(prep, **send_kwargs)
  File "c:\SDK\Anaconda2\lib\site-packages\requests\sessions.py", line 643, in send
    r = adapter.send(request, **kwargs)
  File "c:\SDK\Anaconda2\lib\site-packages\requests\adapters.py", line 514, in send
    raise SSLError(e, request=request)
SSLError: HTTPSConnectionPool(host='www.notifymydevice.com', port=443): Max retries exceeded with url: /push (Caused by SSLError(SSLError("bad handshake: Error([('SSL routines', 'ssl3_get_server_certificate', 'certificate verify failed')],)",),))

2020:06:14 04:50:34:023000 ~ Traceback (most recent call last):
  File "c:\SDK\Anaconda2\lib\site-packages\notify\notify.py", line 158, in nmd
    a = requests.post(url, data = data, timeout = timeout)
  File "c:\SDK\Anaconda2\lib\site-packages\requests\api.py", line 119, in post
    return request('post', url, data=data, json=json, **kwargs)
  File "c:\SDK\Anaconda2\lib\site-packages\requests\api.py", line 61, in request
    return session.request(method=method, url=url, **kwargs)
  File "c:\SDK\Anaconda2\lib\site-packages\requests\sessions.py", line 530, in request
    resp = self.send(prep, **send_kwargs)
  File "c:\SDK\Anaconda2\lib\site-packages\requests\sessions.py", line 643, in send
    r = adapter.send(request, **kwargs)
  File "c:\SDK\Anaconda2\lib\site-packages\requests\adapters.py", line 514, in send
    raise SSLError(e, request=request)
SSLError: HTTPSConnectionPool(host='www.notifymydevice.com', port=443): Max retries exceeded with url: /push (Caused by SSLError(SSLError("bad handshake: Error([('SSL routines', 'ssl3_get_server_certificate', 'certificate verify failed')],)",),))

2020:06:15 05:21:20:271000 ~ Traceback (most recent call last):
  File "c:\SDK\Anaconda2\lib\site-packages\notify\notify.py", line 158, in nmd
    a = requests.post(url, data = data, timeout = timeout)
  File "c:\SDK\Anaconda2\lib\site-packages\requests\api.py", line 119, in post
    return request('post', url, data=data, json=json, **kwargs)
  File "c:\SDK\Anaconda2\lib\site-packages\requests\api.py", line 61, in request
    return session.request(method=method, url=url, **kwargs)
  File "c:\SDK\Anaconda2\lib\site-packages\requests\sessions.py", line 530, in request
    resp = self.send(prep, **send_kwargs)
  File "c:\SDK\Anaconda2\lib\site-packages\requests\sessions.py", line 643, in send
    r = adapter.send(request, **kwargs)
  File "c:\SDK\Anaconda2\lib\site-packages\requests\adapters.py", line 514, in send
    raise SSLError(e, request=request)
SSLError: HTTPSConnectionPool(host='www.notifymydevice.com', port=443): Max retries exceeded with url: /push (Caused by SSLError(SSLError("bad handshake: Error([('SSL routines', 'ssl3_get_server_certificate', 'certificate verify failed')],)",),))

2020:06:16 04:21:59:019000 ~ Traceback (most recent call last):
  File "c:\SDK\Anaconda2\lib\site-packages\notify\notify.py", line 158, in nmd
    a = requests.post(url, data = data, timeout = timeout)
  File "c:\SDK\Anaconda2\lib\site-packages\requests\api.py", line 119, in post
    return request('post', url, data=data, json=json, **kwargs)
  File "c:\SDK\Anaconda2\lib\site-packages\requests\api.py", line 61, in request
    return session.request(method=method, url=url, **kwargs)
  File "c:\SDK\Anaconda2\lib\site-packages\requests\sessions.py", line 530, in request
    resp = self.send(prep, **send_kwargs)
  File "c:\SDK\Anaconda2\lib\site-packages\requests\sessions.py", line 643, in send
    r = adapter.send(request, **kwargs)
  File "c:\SDK\Anaconda2\lib\site-packages\requests\adapters.py", line 514, in send
    raise SSLError(e, request=request)
SSLError: HTTPSConnectionPool(host='www.notifymydevice.com', port=443): Max retries exceeded with url: /push (Caused by SSLError(SSLError("bad handshake: Error([('SSL routines', 'ssl3_get_server_certificate', 'certificate verify failed')],)",),))

